Workbook

Sheet Cover Sheet
A1: NILE Platform — Production Support
A2: Monthly Issue Report · May 2026 · Auto-generated
A5: Total Issues | C5: Pipeline Schedule | E5: Spooler issue | G5: Needs Review
A6: =COUNTIF('Raw — May 2026'!$V$3:$V$10000,"<>") | C6: 29 | E6: 26 | G6: =TEXT(IF(COUNTIF('Raw — May 2026'!$V$3:$V$10000,"<>")>0,COUNTIF('Raw — May 2026'!$V$3:$V$10000,"Other")/COUNTIF('Raw — May 2026'!$V$3:$V$10000,"<>"),0),"0.0%")
A9: ⚠ Health Status: Needs Review rate is high (42.6%). Top issue: Pipeline Schedule (29). Consider expanding keywords in config.py.
A12: Category | B12: Count | C12: % Share | D12: vs Last Month | E12: Trend Bar
A13: Configuration Issue | B13: 20 | C13: 9.6% | D13: ▼ -11 | E13: ████
A14: File Issue | B14: 13 | C14: 6.2% | D14: ▼ -15 | E14: ███
A15: Spooler issue | B15: 26 | C15: 12.4% | D15: ▲ +4 | E15: ██████
A16: Data Issue | B16: 6 | C16: 2.9% | D16: ▼ -6 | E16: █
A17: File Missing | B17: 3 | C17: 1.4% | D17: ▼ -12 | E17: █
A18: Unmatched raw data count | B18: 3 | C18: 1.4% | D18: — same | E18: █
A19: Pipeline Schedule | B19: 29 | C19: 13.9% | D19: ▲ +4 | E19: ███████
A20: DB Issue | B20: 2 | C20: 1.0% | D20: — same | E20: █
A21: Schema issue | B21: 7 | C21: 3.3% | D21: — same | E21: ██
A22: Issue Platform | B22: 11 | C22: 5.3% | D22: ▲ +7 | E22: ██
A23: Other | B23: 89 | C23: 42.6% | D23: ▲ +6 | E23: ████████████████████
A24: TOTAL | B24: 209 | C24: 100%
A26: All figures are auto-generated from the Jira export. Re-run the tracker to refresh. Needs Review tickets require manual categorization.

Sheet All Months Summary
A1: NILE Platform — Production Support | All Months Issue Summary
A3: Category | B3: Apr 2026 | C3: % Share | D3: May 2026 | E3: % Share
A4: Configuration Issue | B4: =COUNTIF('Raw — Apr 2026'!$V$3:$V$10000,"Configuration Issue") | C4: =IF(B16>0,B4/B16,0) | D4: =COUNTIF('Raw — May 2026'!$V$3:$V$10000,"Configuration Issue") | E4: =IF(D16>0,D4/D16,0)
A5: File Issue | B5: =COUNTIF('Raw — Apr 2026'!$V$3:$V$10000,"File Issue") | C5: =IF(B16>0,B5/B16,0) | D5: =COUNTIF('Raw — May 2026'!$V$3:$V$10000,"File Issue") | E5: =IF(D16>0,D5/D16,0)
A6: Spooler issue | B6: =COUNTIF('Raw — Apr 2026'!$V$3:$V$10000,"Spooler issue") | C6: =IF(B16>0,B6/B16,0) | D6: =COUNTIF('Raw — May 2026'!$V$3:$V$10000,"Spooler issue") | E6: =IF(D16>0,D6/D16,0)
A7: Data Issue | B7: =COUNTIF('Raw — Apr 2026'!$V$3:$V$10000,"Data Issue") | C7: =IF(B16>0,B7/B16,0) | D7: =COUNTIF('Raw — May 2026'!$V$3:$V$10000,"Data Issue") | E7: =IF(D16>0,D7/D16,0)
A8: File Missing | B8: =COUNTIF('Raw — Apr 2026'!$V$3:$V$10000,"File Missing") | C8: =IF(B16>0,B8/B16,0) | D8: =COUNTIF('Raw — May 2026'!$V$3:$V$10000,"File Missing") | E8: =IF(D16>0,D8/D16,0)
A9: Unmatched raw data count | B9: =COUNTIF('Raw — Apr 2026'!$V$3:$V$10000,"Unmatched raw data count") | C9: =IF(B16>0,B9/B16,0) | D9: =COUNTIF('Raw — May 2026'!$V$3:$V$10000,"Unmatched raw data count") | E9: =IF(D16>0,D9/D16,0)
A10: Pipeline Schedule | B10: =COUNTIF('Raw — Apr 2026'!$V$3:$V$10000,"Pipeline Schedule") | C10: =IF(B16>0,B10/B16,0) | D10: =COUNTIF('Raw — May 2026'!$V$3:$V$10000,"Pipeline Schedule") | E10: =IF(D16>0,D10/D16,0)
A11: DB Issue | B11: =COUNTIF('Raw — Apr 2026'!$V$3:$V$10000,"DB Issue") | C11: =IF(B16>0,B11/B16,0) | D11: =COUNTIF('Raw — May 2026'!$V$3:$V$10000,"DB Issue") | E11: =IF(D16>0,D11/D16,0)
A12: Metric drop | B12: =COUNTIF('Raw — Apr 2026'!$V$3:$V$10000,"Metric drop") | C12: =IF(B16>0,B12/B16,0) | D12: =COUNTIF('Raw — May 2026'!$V$3:$V$10000,"Metric drop") | E12: =IF(D16>0,D12/D16,0)
A13: Schema issue | B13: =COUNTIF('Raw — Apr 2026'!$V$3:$V$10000,"Schema issue") | C13: =IF(B16>0,B13/B16,0) | D13: =COUNTIF('Raw — May 2026'!$V$3:$V$10000,"Schema issue") | E13: =IF(D16>0,D13/D16,0)
A14: Issue Platform | B14: =COUNTIF('Raw — Apr 2026'!$V$3:$V$10000,"Issue Platform") | C14: =IF(B16>0,B14/B16,0) | D14: =COUNTIF('Raw — May 2026'!$V$3:$V$10000,"Issue Platform") | E14: =IF(D16>0,D14/D16,0)
A15: Other | B15: =COUNTIF('Raw — Apr 2026'!$V$3:$V$10000,"Other") | C15: =IF(B16>0,B15/B16,0) | D15: =COUNTIF('Raw — May 2026'!$V$3:$V$10000,"Other") | E15: =IF(D16>0,D15/D16,0)
A16: TOTAL | B16: =SUM(B4:B15) | C16: 100% | D16: =SUM(D4:D15) | E16: 100%

Sheet Raw — Apr 2026
A1: NILE Pipeline Issues — April 2026
A2: Key | B2: Issue id | C2: Parent id | D2: Summary | E2: Description | F2: Comment | G2: Close Notes | H2: Categories | I2: New Categories | J2: Assign | K2: Status | L2: Created | M2: Updated | N2: Custom field (Assignment Group) | O2: Assignee | P2: Reporter | Q2: Resolution | R2: Custom field (Comments) | S2: Inward issue link (Cloners) | T2: Outward issue link (Cloners) | U2: Inward issue link (Relates) | V2: Category | W2: Review Required
A3: IT-3023323 | B3: IT-3023323 | D3: Monthly pipeline dm-uhc-unet-actian_migration_provider_npi_detail has failed for data date: 202604 | E3: Pipeline dm-uhc-unet-actian_migration_provider_npi_detail has failed with the error message: Source file schema is not matching with the Table Schema, Please check Column names and their Data-types. Please investigate | F3: We are using the dm-uhc-unet-actian_migration_provider_npi_detail _newtemp pipeline, so we won't need to ingest with this pipeline anymore. Thank you melly | G3: Use the _newtemp pipeline to ingest. | H3: Other | I3: Other | K3: Closed | L3: 2026-04-29 | M3: 2026-04-30 | N3: Nile Production Support | O3: Unassigned | P3: Acharya, Suraj | Q3: Resolved | R3: We are using the dm-uhc-unet-actian_migration_provider_npi_detail _newtemp pipeline, so we won't need to ingest with this pipeline anymore. Thank you melly | V3: Schema issue
A4: IT-3023321 | B4: IT-3023321 | D4: HCSCG - History PROF & INST. Files Missing - 04/28/2026 | E4: Hi Nile Team, We are missing HCSCG History Professional and Institutional for 04/24, So please check and provide us an update. hcscg_history_incoming_1 hcscg_ophistory_incoming_1 | G4: Files received and processed successfully. | K4: Closed | L4: 2026-04-29 | M4: 2026-05-01 | N4: Nile Production Support | O4: Unassigned | P4: Gudala, Kumaraswamy | Q4: Closed | V4: File Missing
A5: IT-3023116 | B5: IT-3023116 | D5: dm-bcbs_ma_bcbs_ma-actian_migration_caqh_and_bmc_workflow_CHC_BCBS_MA_ADH_CAQH_Load_NILE | E5: Weekly pipeline has been failing for over a month. The client has been sending file as CAQH File.* instead of CAQH file.* (lowercase). Pipeline is manually rerun each week using Override Parameters to complete successfully old {"source_data_pattern": "CAQH file .*.xlsx", "source_entity_1_file_pattern": "CAQH file .*.xlsx"} new {"source_data_pattern": "CAQH File .*.xlsx", "source_entity_1_file_pattern": "CAQH File.*.xlsx"} Suggestion : set source_data_pattern and source_entity_1_file_pattern to CAQH. * . xslx to account for both variations the client sends, or CAQH File . .xlsx | G5: Updated {"source_data_pattern": "CAQH File .*.xlsx", "source_entity_1_file_pattern": "CAQH File.*.xlsx"} | H5: Other | I5: Other | K5: Closed | L5: 2026-04-29 | M5: 2026-04-29 | N5: Nile Production Support | O5: Unassigned | P5: Easley, Keaton | Q5: Resolved | V5: Configuration Issue
A6: IT-3022913 | B6: IT-3022913 | D6: BCBS_MA CAQH files not ingested for April '26 | E6: Hello Nile team , BCBS_MA CAQH weekly files have not been ingested for April '26. The latest file we have in SQL is :- C*AQH File 20260407.xlsx* pipeline :- dm-bcbs_ma_bcbs_ma-actian_migration_caqh_and_bmc_workflow_CHC_BCBS_MA_ADH_CAQH_Load_NILE Missing files that Nile received but ingestion was not complete : - C*AQH File 20260414.xlsx* C*AQH File 20260421.xlsx* C*AQH File 20260428.xlsx* Thanks, Teena. | G6: Ingestion completed for all outstanding files | K6: Closed | L6: 2026-04-29 | M6: 2026-04-30 | N6: Nile Production Support | O6: Unassigned | P6: Vandanath, Teena | Q6: Closed | V6: File Issue
A7: IT-3022274 | B7: IT-3022274 | D7: Request for Data Validation: Claim Raw/model vs NILE Raw Data (Claims Header Fields) | E7: Client: BCBS_ND We are validating data in the ARK platform and observed that all fields in the Claims Header are populated from the Claim model, which in turn is sourced from Claim raw data. The values in the Claim model and raw data match exactly with the Claims Header, indicating that the data is loading as per the current logic. Since the Claim model data originates from NILE, we would like to understand how the raw data from NILE is structured and whether any transformations are applied to the relevant columns before being delivered downstream. Currently, we do not have visibility into the NILE raw files/tables to verify this. For example members CH_PATIENT_CLIENT_MASTER_ID (member_id) IN (135557853, 66442765, 93553925), OPS has requested validation of the raw data to determine whether the client is sending multiple policy/UMI plans per member. The goal is to identify whether the root cause of the mapping issue is related to how the client sends the data or a Cotiviti mapping issue. The columns to validate in the Claims Header are [PatNum] , [PatFirstName] , [PatLastName] , [EmployerName] , and [GroupNum] , with corresponding Claim Model/Raw columns CH_PATIENT_CLIENT_ID, CH_PATIENT_FIRST_NAME, CH_PATIENT_LAST_NAME, CH_GROUP_NAME, and CH_GROUP_NUMBER. | H7: Other | I7: Other | K7: Open | L7: 2026-04-29 | M7: 2026-04-29 | N7: Nile Production Support | O7: Unassigned | P7: Hagelin, Lindsay | Q7: Unresolved | V7: Data Issue
A8: IT-3022254 | B8: IT-3022254 | D8: Update to "MsrLobConcurrencyRates" Table | E8: Please do a full replacement of the existing table. There was an update to the values for a Medicaid state and we need those reflected in SpotCheck for claim accuracy. This is a one off from the normal cadence schedule. | F8: MsrLobConcurrencyRates.xlsx (28 kB) Hello Nile Team. The pipeline and table for this file already exist. Pipeline: dm-mcl-mcl-actian_migration_MsrLobConcurrencyRates The source file is located here: Y:\Ftp\B2B\MCL-NILE\MsrLobConcurrencyRates\2026-04-01\MsrLobConcurrencyRates.xlsx Thanks. Mike Hello Dhakal, Sambeg . I have reviewed the MsrLobConcurrencyRates table and the data looks good. You can close the ticket. Thanks. Mike Knochel, Tanya , Deynarian, Michael the pipeline has failed. Has the table already been updated? It failed at stage trigger BMC. | H8: Other | I8: Other | K8: In Progress (HD1) | L8: 2026-04-29 | M8: 2026-05-06 | N8: Nile Production Support | O8: Unassigned | P8: Knochel, Tanya | Q8: Unresolved | R8: MsrLobConcurrencyRates.xlsx (28 kB) Hello Nile Team. The pipeline and table for this file already exist. Pipeline: dm-mcl-mcl-actian_migration_MsrLobConcurrencyRates The source file is located here: Y:\Ftp\B2B\MCL-NILE\MsrLobConcurrencyRates\2026-04-01\MsrLobConcurrencyRates.xlsx Thanks. Mike Hello Dhakal, Sambeg . I have reviewed the MsrLobConcurrencyRates table and the data looks good. You can close the ticket. Thanks. Mike Knochel, Tanya , Deynarian, Michael the pipeline has failed. Has the table already been updated? It failed at stage trigger BMC. | V8: Pipeline Schedule
A9: IT-3021950 | B9: IT-3021950 | D9: bcbsnjhorizon_facets_no_touch failed due to file path does not exist. | E9: Pipeline: bcbsnjhorizon_facets_no_touch Got failed in Preprocessor [data-preprocessor] stage due to file path does not exist, since the files is already available in spooler location. Please do check on the file path location for the file. | F9: Hi Raya, Birajan file processed Thanks Satish Devatha | G9: file processed | H9: Other | I9: Other | K9: Closed | L9: 2026-04-29 | M9: 2026-04-29 | N9: Nile Production Support | O9: Unassigned | P9: Raya, Birajan | Q9: Resolved | R9: Hi Raya, Birajan file processed Thanks Satish Devatha | V9: File Issue
A10: IT-3021831 | B10: IT-3021831 | D10: CLONE - Peer Review for Aetna-Trad-SCM BMC pipeline Optimization | E10: Review all the required conditions for the BMC/child pipelines: Prechecks pipeline version to be updated to Latest Remove unwanted parameters from the pipeline All the child pipelines need to be published BMC pipeline needs to be published and Scheduled/Subscribe option need to be enabled. Update all the prod documents with latest pipeline versions. | G10: Since it's a direct bmc pipeline it doesn't require any changes. | H10: Other | I10: Other | K10: Closed | L10: 2026-04-29 | M10: 2026-04-30 | N10: Nile Production Support | O10: Unassigned | P10: Kamsetty, Sravani | Q10: Done | V10: Configuration Issue
A11: IT-3021830 | B11: IT-3021830 | D11: [BCBS_MI]-Update prechecks for BMC and publish all the child pipelines. | E11: Update precheck with pipeline version as latest and remove all the unnecessary parameters from the pipeline. Publish all the child pipelines and modify subscribe BMC pipeline versions to latest. | F11: BMC Pipeline prechecks conditions for pipeline version is updated to latest. Published and scheduled the latest BMC version pipeline. FYI: trigger_bmc_workflow-bcbs_mi_bcbs_mi_monthly Version: V1.6 | G11: BMC Pipeline prechecks conditions for pipeline version is updated to latest. Published and scheduled the latest BMC version pipeline. FYI: trigger_bmc_workflow-bcbs_mi_bcbs_mi_monthly Version: V1.6 | H11: Other | I11: Other | K11: Closed | L11: 2026-04-29 | M11: 2026-05-01 | N11: Nile Production Support | O11: Unassigned | P11: Kamsetty, Sravani | Q11: Resolved | R11: BMC Pipeline prechecks conditions for pipeline version is updated to latest. Published and scheduled the latest BMC version pipeline. FYI: trigger_bmc_workflow-bcbs_mi_bcbs_mi_monthly Version: V1.6 | V11: Configuration Issue
A12: IT-3021086 | B12: IT-3021086 | D12: Unmatched cosmosfaclcontractcategory raw data count - 20260428_1 - prod - dm-uhc-cosmos-actian_migration_cosmosfaclcontractcategory | E12: File name(s) COSMOS_FACL_CONTRACT_CATEGORY_OUT_HIST_APR26.txt Rejected records Impala table prod_niledataingestion_unrestricted.uhc_cosmos_raw_cosmosfaclcontractcategory_rejected_records_20260428_1 File data line count 201469543 Total raw data line count 201469543 Ingested row count 0 | F12: Hi Raya, Birajan , There is an extra column added to the end of the record on the existing schema .so, entire file is being rejected. Total columns as per the schema : 66 new file columns : 67 Need to check with EDM engineer. schema updated and file processed successfully. | G12: File processed successfully. | H12: Other | I12: Other | K12: Closed | L12: 2026-04-29 | M12: 2026-05-05 | N12: Nile Production Support | O12: Unassigned | P12: Raya, Birajan | Q12: Resolved | R12: Hi Raya, Birajan , There is an extra column added to the end of the record on the existing schema .so, entire file is being rejected. Total columns as per the schema : 66 new file columns : 67 Need to check with EDM engineer. schema updated and file processed successfully. | V12: Data Issue
A13: IT-3020658 | B13: IT-3020658 | D13: NAS Spoolers failed and pipeline not completed,Hue browser not working in production environment. | E13: Today, we experienced a Hadoop issue where spoolers failed, pipelines got stuck, and the Hue browser became inaccessible. | F13: The HUE browser is not accessible, and from the Nile side all NAS spoolers have failed. The failure occurred while trying to write files to HDFS. The error indicates that the HDFS NameNode is in safe mode, which prevents any file creation or write operations. Because of this, the spooler is unable to write files to the HDFS path, causing all spooling processes to fail. The system will remain in safe mode until the required block threshold is met, after which it should automatically turn off and resume normal operations. Hadoop noticed the issue and rolling restart the cluster. Instatly issue was resolved. After sometime pipeline are not running as expected. we notify and connected with different teams. They noticed the issue and resolved with the cluster restart. Summary: (Object(s) that caused the issue (host names, etc), issues/symptoms, include a link to the alert if there was one) - There are 20 missing blocks due to which Pipelines are unable to pick any jobs Resolution: (Actions taken by support teams to resolve the issue, Team/Individual that fixed the issue, additional tickets involved) - Restarted the Nile prod cluster (usapnlhdpe01) Summary: (Object(s) that caused the issue (host names, etc), issues/symptoms, include a link to the alert if there was one) - There are 20 missing blocks due to which Pipelines are unable to pick any jobs Resolution: (Actions taken by support teams to resolve the issue, Team/Individual that fixed the issue, additional tickets involved) - Restarted the Nile prod cluster (usapnlhdpe01) | G13: Summary: (Object(s) that caused the issue (host names, etc), issues/symptoms, include a link to the alert if there was one) - There are 20 missing blocks due to which Pipelines are unable to pick any jobs Resolution: (Actions taken by support teams to resolve the issue, Team/Individual that fixed the issue, additional tickets involved) - Restarted the Nile prod cluster (usapnlhdpe01) | H13: Other | I13: Other | K13: Closed | L13: 2026-04-29 | M13: 2026-04-29 | N13: Nile Production Support | O13: Unassigned | P13: Kantimahanti, Ravisankar | Q13: Resolved | R13: The HUE browser is not accessible, and from the Nile side all NAS spoolers have failed. The failure occurred while trying to write files to HDFS. The error indicates that the HDFS NameNode is in safe mode, which prevents any file creation or write operations. Because of this, the spooler is unable to write files to the HDFS path, causing all spooling processes to fail. The system will remain in safe mode until the required block threshold is met, after which it should automatically turn off and resume normal operations. Hadoop noticed the issue and rolling restart the cluster. Instatly issue was resolved. After sometime pipeline are not running as expected. we notify and connected with different teams. They noticed the issue and resolved with the cluster restart. Summary: (Object(s) that caused the issue (host names, etc), issues/symptoms, include a link to the alert if there was one) - There are 20 missing blocks due to which Pipelines are unable to pick any jobs Resolution: (Actions taken by support teams to resolve the issue, Team/Individual that fixed the issue, additional tickets involved) - Restarted the Nile prod cluster (usapnlhdpe01) Summary: (Object(s) that caused the issue (host names, etc), issues/symptoms, include a link to the alert if there was one) - There are 20 missing blocks due to which Pipelines are unable to pick any jobs Resolution: (Actions taken by support teams to resolve the issue, Team/Individual that fixed the issue, additional tickets involved) - Restarted the Nile prod cluster (usapnlhdpe01) | V13: Spooler issue
A14: IT-3020610 | B14: IT-3020610 | D14: Update the tracker with the newly deployed History Lean Ingestion pipelines for DevotedHealth that are now live in production. | E14: Hello Jani, Shaik , We have scheduled the devotedhealth - devotedhealth history lean ingestion pipelines in production, and these will be used going forward. Please note that for TBA, we will continue using the currently running Slim_Refactoring pipeline for devotedhealth - devotedhealth, as its estimated runtime is already around 13–14 minutes. The following is the list of old pipeline Ids replaced by the lean ingestion pipelines. 2023-02-27-54910254 -> 2026-03-30-111442046 reports: 2026-03-30-90594816 2023-02-27-52996445 -> 2026-03-30-111388968 reports: 2026-03-30-90568473 Thank You | G14: Details recorded accordingly. | H14: Other | I14: Other | K14: Closed | L14: 2026-04-29 | M14: 2026-05-06 | N14: Nile Production Support | O14: Unassigned | P14: Karakavalasa, SriVarshini | Q14: Resolved | V14: Other | W14: Yes
A15: IT-3020001 | B15: IT-3020001 | D15: CIGMC Prof. History File Failure 4/25/2026 | E15: Hi Nile team, The below file has failed for being out of sequence because it is using a seq# that was previously processed on 02/11/2026. Can you please have the client correct this and resend for processing? Failure: { } CIGMC|H| 0027710 |20260208|1|R TRAILER|1|20260208|160050 cigmc_history_incoming_113147 (1) Total Lines Processed for Run : 1 File Processing Information: ---------------------------------------------------------------------------------------------------- File : cigmc_history_incoming_113147.04-25-2026_1255 QA Status : FAILED Reason : FAILED- out-of-sequence Previously processed File: { } CIGMC|H| 0027710 |20260211|142|R TRAILER|142|20260211|160050 cigmc_ophistory_incoming_125706 (142) Total Lines Processed for Run : 142 File Processing Information: ---------------------------------------------------------------------------------------------------- File : cigmc_ophistory_incoming_125706.02-11-2026_1311 QA Status : PASSED File Run Completed : 02-11-2026_1311 | F15: Requested for the replacement file to the client Email subject reference: replacement file needed with corrected sequence number for CIGNA Medicare history professional file (2026/04/25) Client confirmed the corrected file was sent as cigmc_history_professional_incoming_20260429_100103.txt. File was received by Nile and processed successfully 4/29 around 11AMEST. Production Control team confirmed today that this file was successful on their side as well. File : cigmc_history_incoming_100103.04-29-2026_1115 QA Status : PASSED File Run Completed : 04-29-2026_1115 | G15: Client confirmed the corrected file was sent as cigmc_history_professional_incoming_20260429_100103.txt. File was received by Nile and processed successfully 4/29 around 11AMEST. Production Control team confirmed today that this file was successful on their side as well. File : cigmc_history_incoming_100103.04-29-2026_1115 QA Status : PASSED File Run Completed : 04-29-2026_1115 | H15: Other | I15: Other | K15: Closed | L15: 2026-04-28 | M15: 2026-05-05 | N15: Nile Production Support | O15: Unassigned | P15: Daniels, Ben | Q15: Resolved | R15: Requested for the replacement file to the client Email subject reference: replacement file needed with corrected sequence number for CIGNA Medicare history professional file (2026/04/25) Client confirmed the corrected file was sent as cigmc_history_professional_incoming_20260429_100103.txt. File was received by Nile and processed successfully 4/29 around 11AMEST. Production Control team confirmed today that this file was successful on their side as well. File : cigmc_history_incoming_100103.04-29-2026_1115 QA Status : PASSED File Run Completed : 04-29-2026_1115 | V15: File Issue
A16: IT-3019955 | B16: IT-3019955 | D16: TXCHP Institutional/TBA Files Failing 4/28/2026 | E16: We are experiencing a situation similar to IT-3004600 - TXCHP Institutional/TBA & History Files Failing 4/21/2026 TXCHP is continuing to fail. We have confirmed the files have been previously run in 2025. See the failed file list below. Can you please confirm if the client intentionally sent these files? Ticket: txchp_daily_incoming_1.04-28-2026_1700 txchp_daily_incoming_1.04-28-2026_1740 txchp_daily_incoming_1.04-28-2026_1815 txchp_outpatient_incoming_1.04-28-2026_1830 txchp_daily_incoming_1.04-28-2026_1855 txchp_outpatient_incoming_1.04-28-2026_1910 txchp_daily_incoming_1.04-28-2026_1934 txchp_outpatient_incoming_1.04-28-2026_1950 txchp_daily_incoming_1.04-28-2026_2023 txchp_outpatient_incoming_1.04-28-2026_2035 txchp_outpatient_incoming_1.04-28-2026_2120 txchp_daily_incoming_1.04-28-2026_2130 txchp_outpatient_incoming_1.04-28-2026_2210 txchp_daily_incoming_1.04-28-2026_2210 | F16: Melly's email (question): RE: IT-3019955 TXCHP Institutional/TBA Files Failing 4/28/2026 Need to understand what the source files are.. RE: IT-3019955 TXCHP Institutional/TBA Files Failing 4/28/2026 | H16: Other | I16: Other | K16: On Hold | L16: 2026-04-28 | M16: 2026-05-05 | N16: Nile Production Support | O16: Unassigned | P16: Edwards, Andrea | Q16: Unresolved | R16: Melly's email (question): RE: IT-3019955 TXCHP Institutional/TBA Files Failing 4/28/2026 Need to understand what the source files are.. RE: IT-3019955 TXCHP Institutional/TBA Files Failing 4/28/2026 | V16: File Issue
A17: IT-3019608 | B17: IT-3019608 | D17: Pipeline: dm-amerihealth-results-actian_migration_claims_detail | Data Date: 2026/04/28 | Failure | E17: Pipeline: dm-amerihealth-results-actian_migration_claims_detail , Version: V1.3 , Data Date: 2026/04/28 Error Message: Exiting Process with failure.Key source-file: /dataingestionprod/restricted/218-amerihealth-results/rawincoming/2024-09-20-102280221/1.3/125369.115465/20260428/1/NCDS_ClaimsRecovery.03132026.zip/NCDS_ClaimsRecovery.03132026.txt is zero-byte and Size: 0 . Stopping Ingestion Process as configured as mandatory file (Source section). We got CONFIRMATION from Karyn (EDM) to proceed with the loading. Thank you | F17: Hi Enid Ike pipeline completed Thanks Satish Devatha | G17: pipeline completed | H17: Other | I17: Other | K17: Closed | L17: 2026-04-28 | M17: 2026-04-28 | N17: Nile Production Support | O17: Unassigned | P17: Enid Ike | Q17: Resolved | R17: Hi Enid Ike pipeline completed Thanks Satish Devatha | V17: Other | W17: Yes
A18: IT-3019286 | B18: IT-3019286 | D18: BCNAM GWF Flag | E18: Hello, Currently, BCNAM is fully GWF eligible and everything on our end is configured this way. However, we are still seeing claims come through as not GWF eligible. We were wondering if this field is hardcoded at the GDF/CDF level. Can you please provide how these fields are currently mapped? GDF: CH_US_ONLY_INDICATOR CDF: US_ONLY_YN | F18: Hi Giri, Kushal , Good morning. I have verified the mappings and provided the below information to here. There is no raw field mapping for the below field in the GDF. CAST(NULL AS STRING) AS CH_US_ONLY_INDICATOR No mapping for the US_ONLY_YN Details have been conveyed to the customer. awaiting response. | H18: Other | I18: Other | K18: On Hold | L18: 2026-04-28 | M18: 2026-05-05 | N18: Nile Production Support | O18: Unassigned | P18: Giri, Kushal | Q18: Unresolved | R18: Hi Giri, Kushal , Good morning. I have verified the mappings and provided the below information to here. There is no raw field mapping for the below field in the GDF. CAST(NULL AS STRING) AS CH_US_ONLY_INDICATOR No mapping for the US_ONLY_YN Details have been conveyed to the customer. awaiting response. | V18: Configuration Issue
A19: IT-3018431 | B19: IT-3018431 | D19: Update to Molina post pay claim extract file | E19: Per the attached email from Molina, an update is being made to Molina’s post pay claim extract file, go live 5/28/2026. Email body from original Molina notification: Our IT will be making a change to the post-pay CLAIMS Extract. Go Live – 5/28/2026 Change: Addition of field at the end of the file New field: Provider_Adjust_Amount – This field now contains the Medicare Sequestration amount on a claim line (net_amt field is unchanged, but now the sequestration amt is explicitly listed in this field) Trey Simpson – AVP, Payment Integrity – Molina Healthcare, Inc. | F19: RE_ Update to Claims Extract.msg (135 kB) Hi Madel, William Does the change apply to all claims? Does the field need to be immediately displayed or is it to be displayed starting on the go-live date? cc Devatha, Satish | H19: Other | I19: Other | K19: Open | L19: 2026-04-28 | M19: 2026-04-29 | N19: Nile Production Support | O19: Unassigned | P19: Madel, William | Q19: Unresolved | R19: RE_ Update to Claims Extract.msg (135 kB) Hi Madel, William Does the change apply to all claims? Does the field need to be immediately displayed or is it to be displayed starting on the go-live date? cc Devatha, Satish | V19: File Issue
A20: IT-3018019 | B20: IT-3018019 | D20: Optumcare RCCV Professional Prod Transition Documents | E20: Hello Team, Please find the prod transition checklist documents for Optumcare RCCV Professional below: Checklist: Optumcare-RCCV_DataIgestion_Production_Job_Transition_Checklist.docx Escalation Doc: OptumCare_Joint Data Escalation Plan Enterprise External 20250424.xlsx I have created a ticket for document review: https://jira2.cotiviti.com/browse/NDICR-5409 | G20: Documents reviewed, Details reviewed and recorded and transition scheduled for today. | H20: Other | I20: Other | K20: Closed | L20: 2026-04-28 | M20: 2026-05-05 | N20: Nile Production Support | O20: Unassigned | P20: Shaik, Parveena | Q20: Resolved | V20: Other | W20: Yes
A21: IT-3017779 | B21: IT-3017779 | D21: Wellmark 3ppmo file Investigation | E21: The client informed that 3PPMO response file was not received. Upon Initial investigation, we found that #PPMO file was not received. Need further investigation on this. | F21: 3PPMO file has not been received from client server to axway itself. Verified with MFT team Asha and could not find the file from client. Sent an email for confirmation: Re: WMK PPMO - welex files not received 04/27/2026 Files received and processed successfully. | G21: Files received and processed successfully. | H21: Other | I21: Other | K21: Closed | L21: 2026-04-28 | M21: 2026-05-04 | N21: Nile Production Support | O21: Unassigned | P21: Bhattarai, Krishna | Q21: Resolved | R21: 3PPMO file has not been received from client server to axway itself. Verified with MFT team Asha and could not find the file from client. Sent an email for confirmation: Re: WMK PPMO - welex files not received 04/27/2026 Files received and processed successfully. | V21: Issue Platform
A22: IT-3017677 | B22: IT-3017677 | D22: dm-aetna-hrp-actian_migration_caqh got failed for 04/17 | E22: dm-aetna-hrp-actian_migration_caqh got failed for 04/17. Issue show the error not all mandatory file received but we have the files. It looks like below aetna -traditional pipeline processes the same file as well and it is also getting failed with the similar reason. dm-aetna-traditional-actian_migration_caqh | F22: Seems source filename is not having any issue. It's restricted client and need to check the unzipped files. Please let US people know so they can resolve. copied, moved files. re-spooled. ran pipeline, failed. | H22: Other | I22: Other | K22: In Progress (HD1) | L22: 2026-04-28 | M22: 2026-04-30 | N22: Nile Production Support | O22: Unassigned | P22: Aryal, Neerajan | Q22: Unresolved | R22: Seems source filename is not having any issue. It's restricted client and need to check the unzipped files. Please let US people know so they can resolve. copied, moved files. re-spooled. ran pipeline, failed. | V22: Pipeline Schedule
A23: IT-3017668 | B23: IT-3017668 | D23: UHC PNICE Transition | E23: UHC PNICE Transition | G23: Details recorded after reviewing the documents. | H23: Other | I23: Other | K23: Closed | L23: 2026-04-28 | M23: 2026-05-04 | N23: Nile Production Support | O23: Unassigned | P23: Bobbiti, Jithendra | Q23: Resolved | V23: Other | W23: Yes
A24: IT-3017655 | B24: IT-3017655 | D24: Production Transition - Tufts-Diamond | E24: Production Transition - Tufts-Diamond RCCV 2 pipelines Inpatient & Iphistory | F24: Waiting for the transition. also, the feedback fixes. | H24: Other | I24: Other | K24: On Hold | L24: 2026-04-28 | M24: 2026-05-05 | N24: Nile Production Support | O24: Unassigned | P24: Vutukuri, Praveen | Q24: Unresolved | R24: Waiting for the transition. also, the feedback fixes. | V24: Other | W24: Yes
A25: IT-3017640 | B25: IT-3017640 | D25: Wellcare Pipelines got failed | E25: dm-wellcare_wellcare_actian_migration_claim_header_icd10 Pipeline got failed on Fail Stage-raw_data_ingestion_error [fail] Stage. dm-wellcare-wellcare-mem_prov_claims_ingestion — Unmatched Raw Data Count Issue. Email Sub: Unmatched claimsheader_ark raw data count - 20260427_1 - prod - dm-wellcare-wellcare-mem_prov_claims_ingestion | F25: We have rejected records for wellcare claim header file for 20260427. Checking with EDM team. Pipeline processed successfully. | G25: Pipeline processed successfully. | H25: Other | I25: Other | K25: Closed | L25: 2026-04-28 | M25: 2026-04-30 | N25: Nile Production Support | O25: Unassigned | P25: Aryal, Neerajan | Q25: Resolved | R25: We have rejected records for wellcare claim header file for 20260427. Checking with EDM team. Pipeline processed successfully. | V25: Unmatched raw data count
A26: IT-3017571 | B26: IT-3017571 | D26: NAS Spoolers failed in production environment. | E26: we have noticed Nwe have noticed NAS Spoolers failed in production environment. Error: The job failed because our system tried to call another service to get file transfer logs, but that service didn’t respond in time. File spooling failed due to a timeout while calling the external transfer logs API. Error: The job failed because our system tried to call another service to get file transfer logs, but that service didn’t respond in time. File spooling failed due to a timeout while calling the external transfer logs API. | F26: I contacted the Command Center, and they will set up a bridge call with the Unix, Platform, and Axway teams. Service desk ticket from command center https://jiraet.cotiviti.com/browse/IT-3014827 Issue : Summary: (Object(s) that caused the issue (host names, etc), issues/symptoms, include a link to the alert if there was one) Automatic Process of spooling files for PPM clients was affected. The Admin Portal for Transfer2 SFTP URL which is used for the for monitoring or tracking is hung on gad1pt2axcore02 server and caused the log monitoring API not responded. (The NAS spoolers are getting failed to fetch the file from NAS dropbox to Nile HDFS location.) Resolution: (Actions taken by support teams to resolve the issue, Team/Individual that fixed the issue, additional tickets involved) MFT team has restarted the Admin Portal Services to restore the functionality and requested Nile team to use the FQDN url instead of single server url https://transfer2admin.cotiviti.com/api/v2.0/docs/index.html We manually copied the files into ML_Nile B2B and placed them in the HDFS locations. We will monitor the pipelines to ensure the files are delivered on time. We have delivered the files on time. connected with pc team get the confirmation from the user. | G26: We have delivered the files on time. connected with pc team get the confirmation from the user. | H26: Other | I26: Other | K26: Closed | L26: 2026-04-28 | M26: 2026-04-29 | N26: Nile Production Support | O26: Unassigned | P26: Kantimahanti, Ravisankar | Q26: Resolved | R26: I contacted the Command Center, and they will set up a bridge call with the Unix, Platform, and Axway teams. Service desk ticket from command center https://jiraet.cotiviti.com/browse/IT-3014827 Issue : Summary: (Object(s) that caused the issue (host names, etc), issues/symptoms, include a link to the alert if there was one) Automatic Process of spooling files for PPM clients was affected. The Admin Portal for Transfer2 SFTP URL which is used for the for monitoring or tracking is hung on gad1pt2axcore02 server and caused the log monitoring API not responded. (The NAS spoolers are getting failed to fetch the file from NAS dropbox to Nile HDFS location.) Resolution: (Actions taken by support teams to resolve the issue, Team/Individual that fixed the issue, additional tickets involved) MFT team has restarted the Admin Portal Services to restore the functionality and requested Nile team to use the FQDN url instead of single server url https://transfer2admin.cotiviti.com/api/v2.0/docs/index.html We manually copied the files into ML_Nile B2B and placed them in the HDFS locations. We will monitor the pipelines to ensure the files are delivered on time. We have delivered the files on time. connected with pc team get the confirmation from the user. | V26: Spooler issue
A27: IT-3017569 | B27: IT-3017569 | D27: Nile NAS spooler failures | E27: Nile NAS spooler failures Effected clients: caloptima -tba geisinger -tba triples - qnxttricm Carefirst Aetna HRP | F27: Duplicate ticket created. | H27: Other | I27: Other | K27: Cancelled | L27: 2026-04-28 | M27: 2026-04-29 | N27: Nile Production Support | O27: Unassigned | P27: Kamsetty, Sravani | Q27: Cancelled | R27: Duplicate ticket created. | V27: Other | W27: Yes
A28: IT-3017529 | B28: IT-3017529 | D28: Nile NAS spooler failures | E28: Nile NAS spooler failures Effected clients: caloptima -tba geisinger -tba triples - qnxttricm Carefirst Aetna HRP | F28: Nile NAS spoolers failed and Joined command center bridge call. Helped gathering the issue and ran the pipelines manually as a workaround until the issue is fixed. | G28: Nile NAS spoolers failed and Joined command center bridge call. Helped gathering the issue and ran the pipelines manually as a workaround until the issue is fixed. | H28: Other | I28: Other | K28: Closed | L28: 2026-04-28 | M28: 2026-04-28 | N28: Nile Production Support | O28: Unassigned | P28: Kamsetty, Sravani | Q28: Resolved | R28: Nile NAS spoolers failed and Joined command center bridge call. Helped gathering the issue and ran the pipelines manually as a workaround until the issue is fixed. | V28: Spooler issue
A29: IT-3017053 | B29: IT-3017053 | D29: Request to add EDM's distro list to NILE's email notifications | E29: Hi Nile Prod Support team. Please add EDM’s distribution list to NILE’s ingestion report email notifications (see sample attached). EDM’s distribution list for each client is also attached. | F29: Data metric percentage drop hits threshold 202603 - prod - dm-humana-hdap-actian_migration_MEDCLM_RAW_AMBULANCE.msg (84 kB) Late Client File Notification - prod - Kaiser - WA - Kaiser-WA-Actian.msg (70 kB) prod - Cannot kick off bmc workflow CHC_UHC_COSMOS_PROVIDER_INCREMENTAL_NILE for ingestion period 20260428.msg (79 kB) Unmatched caqh raw data count - 20260404_1 - prod - dm-excellus-actian_migration_caqh.msg (77 kB) AuditDistroList-1.xlsx to make sure the email implementation of UHC Cirrus and HCSC is okay for EDM | H29: Other | I29: Other | K29: On Hold | L29: 2026-04-27 | M29: 2026-04-29 | N29: Nile Production Support | O29: Unassigned | P29: Pacete, John | Q29: Unresolved | R29: Data metric percentage drop hits threshold 202603 - prod - dm-humana-hdap-actian_migration_MEDCLM_RAW_AMBULANCE.msg (84 kB) Late Client File Notification - prod - Kaiser - WA - Kaiser-WA-Actian.msg (70 kB) prod - Cannot kick off bmc workflow CHC_UHC_COSMOS_PROVIDER_INCREMENTAL_NILE for ingestion period 20260428.msg (79 kB) Unmatched caqh raw data count - 20260404_1 - prod - dm-excellus-actian_migration_caqh.msg (77 kB) AuditDistroList-1.xlsx to make sure the email implementation of UHC Cirrus and HCSC is okay for EDM | V29: Other | W29: Yes
A30: IT-3016920 | B30: IT-3016920 | D30: Copy files From Nile Prod Raw path to Nile QC Raw path - Aetna Trad | E30: Hi Team, Could you please copy the below mentioned files from the Nile PROD location to the Nile QC location? for the last week files, 04/19/2026 to latest. This request is critical as we have early communicated with prod support team. Nile PROD RAW PATH (Source): /dataingestionprod/raw/unrestricted/5-aetna-traditional Nile Dev RAW PATH (Target): /dataingestionqc/raw/unrestricted/5-aetna-traditional Once copied to QC folder, the owner should be set to "svcpnilediqcraw" and group should be set to "qcunrestricted" and permissions should be 75 | F30: Files Copied | G30: Files Copied | H30: Other | I30: Other | K30: Closed | L30: 2026-04-27 | M30: 2026-04-27 | N30: Nile Production Support | O30: Unassigned | P30: Shivalingu, Naveen | Q30: Resolved | R30: Files Copied | V30: Other | W30: Yes
A31: IT-3016913 | B31: IT-3016913 | D31: Copy files From Nile Prod Raw path to Nile QC Raw path - Aetna Trad | E31: Hi Team, Could you please copy the below mentioned files from the Nile PROD location to the Nile QC location? for the last week files, 04/19/2026 to latest. This request is critical as we have early communicated with prod support team. Nile PROD RAW PATH (Source): /dataingestionprod/raw/unrestricted/5-aetna-traditional Nile Dev RAW PATH (Target): /dataingestionqc/raw/unrestricted/5-aetna-traditional Once copied to QC folder, the owner should be set to "svcpnilediqcraw" and group should be set to "qcunrestricted" and permissions should be 75 | F31: Files are already copied | G31: Files are already copied | H31: Other | I31: Other | K31: Closed | L31: 2026-04-27 | M31: 2026-04-28 | N31: Nile Production Support | O31: Unassigned | P31: Shivalingu, Naveen | Q31: Resolved | R31: Files are already copied | V31: Other | W31: Yes
A32: IT-3016384 | B32: IT-3016384 | D32: Molina Raw Data Needed | E32: Please provide the raw data for the below 5 CCV inpatient files to assist us in researching some data discrepancies that are impacting CCV audits. If possible, please provide the raw files that ultimately feed the below CCV inpatient files. We need to look at the actual raw files from the client, and not the GDF/CDF files that CCV is using (we already have that information). If the actual files cannot be provided, can they be loaded to Hive or Impala for us to query to aid in our research? molhc_inpatient_incoming_1r.02-17-2026_1345 molia_inpatient_incoming_1r.02-17-2026_1345 molky_inpatient_incoming_1r.01-17-2026_1043 molky_inpatient_incoming_1r.02-17-2026_1350 molut_inpatient_incoming_1r.02-17-2026_1400 cc: Free, Ann Waud, Jason | F32: Hi Arevalo, Anna Shared IA,KY,MC and UT raw files Thanks Satish Devatha | G32: Shared IA,KY,MC and UT raw files | H32: Other | I32: Other | K32: Closed | L32: 2026-04-27 | M32: 2026-04-29 | N32: Nile Production Support | O32: Unassigned | P32: Arevalo, Anna | Q32: Resolved | R32: Hi Arevalo, Anna Shared IA,KY,MC and UT raw files Thanks Satish Devatha | V32: Data Issue
A33: IT-3016136 | B33: IT-3016136 | D33: Update spooler name | E33: Hi Team, Could you please update the spooler name in prod? Before : Wellcare-Wellcare_Actian_PBM_MTH_notouch New name : Wellcare-Wellcare_notouch Thank you! | F33: Hi Varghese, Shilpa Anna updated the spooler name Thanks | G33: Updated Spooler name | H33: Other | I33: Other | K33: Closed | L33: 2026-04-27 | M33: 2026-04-27 | N33: Nile Production Support | O33: Unassigned | P33: Varghese, Shilpa Anna | Q33: Resolved | R33: Hi Varghese, Shilpa Anna updated the spooler name Thanks | V33: Other | W33: Yes
A34: IT-3016120 | B34: IT-3016120 | D34: Move two Aetna Trad files to different folders | E34: In HDFS (nile prod server), please move the following files to new locations. Ultimately we want the parent folder of these files to represent a different date (20260411 vs 20260427). Source files: /dataingestiondev/raw/unrestricted/5-aetna-traditional/20260427/M2603M1.ZIP /dataingestiondev/raw/unrestricted/5-aetna-traditional/20260427/M2603M2.ZIP Destinations: /dataingestiondev/raw/unrestricted/5-aetna-traditional/20260411/M2603M1.ZIP /dataingestiondev/raw/unrestricted/5-aetna-traditional/20260411/M2603M2.ZIP | F34: Hi Maguire, Patrick Files moved and updated permissions too please verify | G34: Files moved and updated permissions too | H34: Other | I34: Other | K34: Closed | L34: 2026-04-27 | M34: 2026-04-27 | N34: Nile Production Support | O34: Unassigned | P34: Maguire, Patrick | Q34: Resolved | R34: Hi Maguire, Patrick Files moved and updated permissions too please verify | V34: Other | W34: Yes
A35: IT-3016008 | B35: IT-3016008 | D35: Requesting information for Cigna Gross ID amount dataset | E35: We are looking to learn information on Cigna Gross ID amount dataset as it relates to if it is provided to Nile and if so how and where it can accessed. | H35: Other | I35: Other | K35: In Progress (HD1) | L35: 2026-04-27 | M35: 2026-04-28 | N35: Nile Production Support | O35: Unassigned | P35: Hayes, Denzel | Q35: Unresolved | V35: Other | W35: Yes
A36: IT-3015943 | B36: IT-3015943 | D36: Weekly rccv-bsca-facets-ingest_history_institutional_claims_GDF2_12 got failed due to significant data drop for date 04/25. | E36: Above pipeline got failed due to significant data drop and CSM wants to know the reason for it. Please help investigate and reply to the mail subject: Data metric percentage drop hits threshold 20260425 - prod - rccv-bsca-facets-ingest_history_institutional_claims_GDF2_12 | F36: Hi Kandel, Amik shared the counts with Paul and Rhona Waiting for response on replacement file Got confirmation to add parameter. Now pipeline is running now Hi Kandel, Amik Pipeline completed | G36: Pipeline completed | H36: Other | I36: Other | K36: Closed | L36: 2026-04-27 | M36: 2026-04-29 | N36: Nile Production Support | O36: Unassigned | P36: Kandel, Amik | Q36: Resolved | R36: Hi Kandel, Amik shared the counts with Paul and Rhona Waiting for response on replacement file Got confirmation to add parameter. Now pipeline is running now Hi Kandel, Amik Pipeline completed | V36: Data Issue
A37: IT-3015919 | B37: IT-3015919 | D37: UHC Cosmos Layout update in file 'HCCC_CD_OUT_<>' | E37: Hello Nile Team, There is a layout update in file ‘HCCC_CD_OUT_<>’. Could you please update the data type length of fields HcccDesc to Varchar(24) and HcccSumTxt to Varchar(27) The pipeline name that needs to be updated is prod - dm-uhc-cosmos-actian_migration_HcccCd Thanks, Priya | F37: Dongol, Priya Pipeline dm-uhc-cosmos-actian_migration_HcccCd is now running for data date 2026/04 with updated UDC changes. Dongol, Priya pipeline has ran successfully. Closing ticket. | G37: Pipeline was updated and ran successfully. | H37: Other | I37: Other | K37: Closed | L37: 2026-04-27 | M37: 2026-04-27 | N37: Nile Production Support | O37: Unassigned | P37: Dongol, Priya | Q37: Resolved | R37: Dongol, Priya Pipeline dm-uhc-cosmos-actian_migration_HcccCd is now running for data date 2026/04 with updated UDC changes. Dongol, Priya pipeline has ran successfully. Closing ticket. | V37: Schema issue
A38: IT-3015767 | B38: IT-3015767 | D38: UHC Cosmos/Unet - Layout Update in file ‘DISCOUNT_TYPE_CD_OUT_<>’ | E38: Hello Nile Production Team, We have a layout update on field DscntTypDesc for file ‘DISCOUNT_TYPE_CD_OUT_<>’. I have updated the length of this field in both Cosmos and Unet SQL tables. Could you please update the data type length of fields DscntTypDesc to varchar(1500) in Nile pipelines? Pipeline names are; prod - dm-uhc-cosmos-actian_migration_dscnttype prod - dm-uhc-unet-actian_migration_DscntType Thanks, Priya | F38: Hi Dongol, Priya , Updated UDC for both the pipelines. prod - dm-uhc-cosmos-actian_migration_dscnttype: pipeline is running with the data date 202604 prod - dm-uhc-unet-actian_migration_DscntType: pipeline will run in the next schedule. Dongol, Priya Pipeline: dm-uhc-unet-actian_migration_DscntType. Also ran with data date: 2026/04. So, closing this ticket. Thank you. | G38: Pipeline was updated and ran successfully. | H38: Other | I38: Other | K38: Closed | L38: 2026-04-27 | M38: 2026-05-04 | N38: Nile Production Support | O38: Unassigned | P38: Dongol, Priya | Q38: Resolved | R38: Hi Dongol, Priya , Updated UDC for both the pipelines. prod - dm-uhc-cosmos-actian_migration_dscnttype: pipeline is running with the data date 202604 prod - dm-uhc-unet-actian_migration_DscntType: pipeline will run in the next schedule. Dongol, Priya Pipeline: dm-uhc-unet-actian_migration_DscntType. Also ran with data date: 2026/04. So, closing this ticket. Thank you. | V38: Pipeline Schedule
A39: IT-3015029 | B39: IT-3015029 | D39: Removing unused spoolers with a retention period of ‘-1’ from the production environment. | E39: Removed published spoolers with a retention period of -1 from the production environment, as they were no longer in use. A backup was taken by importing and saving them in a folder prior to deletion. Below is the list of spoolers that were removed from production. | F39: Deleted date: 22-04-2026 | G39: Removed the unused spoolers. | H39: Other | I39: Other | K39: Closed | L39: 2026-04-27 | M39: 2026-04-27 | N39: Nile Production Support | O39: Unassigned | P39: Karakavalasa, SriVarshini | Q39: Resolved | R39: Deleted date: 22-04-2026 | V39: Other | W39: Yes
A40: IT-3014397 | B40: IT-3014397 | D40: Please help ingest 4/13's UHC Cirrus file | E40: Hello team we received Cirrus weekly files on 4/21, the ingestion was on hold because we have to finish some process first. Now the process from our end has completed. The 4/21’s file has been copied over for Nile ingestion would you please help ingest all the files? This is a very time sensitive request, thanks and please let me know if you need additional info. | F40: Hi Tang, Chao , Files spooled and processed from NILE under 20260420 ingestion date. Please check and confirm. Chao confirmed to close the ticket. Thanks. | G40: Files processed from NILE. | H40: Other | I40: Other | K40: Closed | L40: 2026-04-26 | M40: 2026-04-28 | N40: Nile Production Support | O40: Unassigned | P40: Tang, Chao | Q40: Resolved | R40: Hi Tang, Chao , Files spooled and processed from NILE under 20260420 ingestion date. Please check and confirm. Chao confirmed to close the ticket. Thanks. | V40: Spooler issue
...

Sheet Summary — Apr 2026
A1: NILE Pipeline Issue Summary — April 2026
A2: ="Total Tickets: "&TEXT(COUNTIF('Raw — Apr 2026'!$V$3:$V$10000,"<>"),"0")
A4: Category | B4: Count | C4: % Share | D4: vs Last Month | E4: Color Tag
A5: Configuration Issue | B5: =COUNTIF('Raw — Apr 2026'!$V$3:$V$10000,"Configuration Issue") | C5: =IF(COUNTIF('Raw — Apr 2026'!$V$3:$V$10000,"<>")>0,COUNTIF('Raw — Apr 2026'!$V$3:$V$10000,"Configuration Issue")/COUNTIF('Raw — Apr 2026'!$V$3:$V$10000,"<>"),0) | D5: New
A6: File Issue | B6: =COUNTIF('Raw — Apr 2026'!$V$3:$V$10000,"File Issue") | C6: =IF(COUNTIF('Raw — Apr 2026'!$V$3:$V$10000,"<>")>0,COUNTIF('Raw — Apr 2026'!$V$3:$V$10000,"File Issue")/COUNTIF('Raw — Apr 2026'!$V$3:$V$10000,"<>"),0) | D6: New
A7: Spooler issue | B7: =COUNTIF('Raw — Apr 2026'!$V$3:$V$10000,"Spooler issue") | C7: =IF(COUNTIF('Raw — Apr 2026'!$V$3:$V$10000,"<>")>0,COUNTIF('Raw — Apr 2026'!$V$3:$V$10000,"Spooler issue")/COUNTIF('Raw — Apr 2026'!$V$3:$V$10000,"<>"),0) | D7: New
A8: Data Issue | B8: =COUNTIF('Raw — Apr 2026'!$V$3:$V$10000,"Data Issue") | C8: =IF(COUNTIF('Raw — Apr 2026'!$V$3:$V$10000,"<>")>0,COUNTIF('Raw — Apr 2026'!$V$3:$V$10000,"Data Issue")/COUNTIF('Raw — Apr 2026'!$V$3:$V$10000,"<>"),0) | D8: New
A9: File Missing | B9: =COUNTIF('Raw — Apr 2026'!$V$3:$V$10000,"File Missing") | C9: =IF(COUNTIF('Raw — Apr 2026'!$V$3:$V$10000,"<>")>0,COUNTIF('Raw — Apr 2026'!$V$3:$V$10000,"File Missing")/COUNTIF('Raw — Apr 2026'!$V$3:$V$10000,"<>"),0) | D9: New
A10: Unmatched raw data count | B10: =COUNTIF('Raw — Apr 2026'!$V$3:$V$10000,"Unmatched raw data count") | C10: =IF(COUNTIF('Raw — Apr 2026'!$V$3:$V$10000,"<>")>0,COUNTIF('Raw — Apr 2026'!$V$3:$V$10000,"Unmatched raw data count")/COUNTIF('Raw — Apr 2026'!$V$3:$V$10000,"<>"),0) | D10: New
A11: Pipeline Schedule | B11: =COUNTIF('Raw — Apr 2026'!$V$3:$V$10000,"Pipeline Schedule") | C11: =IF(COUNTIF('Raw — Apr 2026'!$V$3:$V$10000,"<>")>0,COUNTIF('Raw — Apr 2026'!$V$3:$V$10000,"Pipeline Schedule")/COUNTIF('Raw — Apr 2026'!$V$3:$V$10000,"<>"),0) | D11: New
A12: DB Issue | B12: =COUNTIF('Raw — Apr 2026'!$V$3:$V$10000,"DB Issue") | C12: =IF(COUNTIF('Raw — Apr 2026'!$V$3:$V$10000,"<>")>0,COUNTIF('Raw — Apr 2026'!$V$3:$V$10000,"DB Issue")/COUNTIF('Raw — Apr 2026'!$V$3:$V$10000,"<>"),0) | D12: New
A13: Metric drop | B13: =COUNTIF('Raw — Apr 2026'!$V$3:$V$10000,"Metric drop") | C13: =IF(COUNTIF('Raw — Apr 2026'!$V$3:$V$10000,"<>")>0,COUNTIF('Raw — Apr 2026'!$V$3:$V$10000,"Metric drop")/COUNTIF('Raw — Apr 2026'!$V$3:$V$10000,"<>"),0) | D13: New
A14: Schema issue | B14: =COUNTIF('Raw — Apr 2026'!$V$3:$V$10000,"Schema issue") | C14: =IF(COUNTIF('Raw — Apr 2026'!$V$3:$V$10000,"<>")>0,COUNTIF('Raw — Apr 2026'!$V$3:$V$10000,"Schema issue")/COUNTIF('Raw — Apr 2026'!$V$3:$V$10000,"<>"),0) | D14: New
A15: Issue Platform | B15: =COUNTIF('Raw — Apr 2026'!$V$3:$V$10000,"Issue Platform") | C15: =IF(COUNTIF('Raw — Apr 2026'!$V$3:$V$10000,"<>")>0,COUNTIF('Raw — Apr 2026'!$V$3:$V$10000,"Issue Platform")/COUNTIF('Raw — Apr 2026'!$V$3:$V$10000,"<>"),0) | D15: New
A16: Other | B16: =COUNTIF('Raw — Apr 2026'!$V$3:$V$10000,"Other") | C16: =IF(COUNTIF('Raw — Apr 2026'!$V$3:$V$10000,"<>")>0,COUNTIF('Raw — Apr 2026'!$V$3:$V$10000,"Other")/COUNTIF('Raw — Apr 2026'!$V$3:$V$10000,"<>"),0) | D16: New
A17: Monthly Total | B17: =SUM(B5:B16) | C17: 100%

Sheet Needs Review — Apr 2026
A1: Needs Review — 83 uncategorized tickets
A2: ="Needs Review count: "&COUNTIF('Raw — Apr 2026'!$V$3:$V$10000,"Other")&" — Change category in Raw Tickets tab, then re-run to refresh this list"
A3: Key | B3: Summary | C3: Description | D3: Comment | E3: Close Notes | F3: Status | G3: Created
A4: IT-3020610 | B4: Update the tracker with the newly deployed History Lean Ingestion pipelines for DevotedHealth that are now live in production. | C4: Hello Jani, Shaik , We have scheduled the devotedhealth - devotedhealth history lean ingestion pipelines in production, and these will be used going forward. Please note that for TBA, we will continue using the currently running Slim_Refactoring pipeline for devotedhealth - devotedhealth, as its estimated runtime is already around 13–14 minutes. The following is the list of old pipeline Ids replaced by the lean ingestion pipelines. 2023-02-27-54910254 -> 2026-03-30-111442046 reports: 2026-03-30-90594816 2023-02-27-52996445 -> 2026-03-30-111388968 reports: 2026-03-30-90568473 Thank You | E4: Details recorded accordingly. | F4: Closed | G4: 2026-04-29
A5: IT-3019608 | B5: Pipeline: dm-amerihealth-results-actian_migration_claims_detail | Data Date: 2026/04/28 | Failure | C5: Pipeline: dm-amerihealth-results-actian_migration_claims_detail , Version: V1.3 , Data Date: 2026/04/28 Error Message: Exiting Process with failure.Key source-file: /dataingestionprod/restricted/218-amerihealth-results/rawincoming/2024-09-20-102280221/1.3/125369.115465/20260428/1/NCDS_ClaimsRecovery.03132026.zip/NCDS_ClaimsRecovery.03132026.txt is zero-byte and Size: 0 . Stopping Ingestion Process as configured as mandatory file (Source section). We got CONFIRMATION from Karyn (EDM) to proceed with the loading. Thank you | D5: Hi Enid Ike pipeline completed Thanks Satish Devatha | E5: pipeline completed | F5: Closed | G5: 2026-04-28
A6: IT-3018019 | B6: Optumcare RCCV Professional Prod Transition Documents | C6: Hello Team, Please find the prod transition checklist documents for Optumcare RCCV Professional below: Checklist: Optumcare-RCCV_DataIgestion_Production_Job_Transition_Checklist.docx Escalation Doc: OptumCare_Joint Data Escalation Plan Enterprise External 20250424.xlsx I have created a ticket for document review: https://jira2.cotiviti.com/browse/NDICR-5409 | E6: Documents reviewed, Details reviewed and recorded and transition scheduled for today. | F6: Closed | G6: 2026-04-28
A7: IT-3017668 | B7: UHC PNICE Transition | C7: UHC PNICE Transition | E7: Details recorded after reviewing the documents. | F7: Closed | G7: 2026-04-28
A8: IT-3017655 | B8: Production Transition - Tufts-Diamond | C8: Production Transition - Tufts-Diamond RCCV 2 pipelines Inpatient & Iphistory | D8: Waiting for the transition. also, the feedback fixes. | F8: On Hold | G8: 2026-04-28
A9: IT-3017569 | B9: Nile NAS spooler failures | C9: Nile NAS spooler failures Effected clients: caloptima -tba geisinger -tba triples - qnxttricm Carefirst Aetna HRP | D9: Duplicate ticket created. | F9: Cancelled | G9: 2026-04-28
A10: IT-3017053 | B10: Request to add EDM's distro list to NILE's email notifications | C10: Hi Nile Prod Support team. Please add EDM’s distribution list to NILE’s ingestion report email notifications (see sample attached). EDM’s distribution list for each client is also attached. | D10: Data metric percentage drop hits threshold 202603 - prod - dm-humana-hdap-actian_migration_MEDCLM_RAW_AMBULANCE.msg (84 kB) Late Client File Notification - prod - Kaiser - WA - Kaiser-WA-Actian.msg (70 kB) prod - Cannot kick off bmc workflow CHC_UHC_COSMOS_PROVIDER_INCREMENTAL_NILE for ingestion period 20260428.msg (79 kB) Unmatched caqh raw data count - 20260404_1 - prod - dm-excellus-actian_migration_caqh.msg (77 kB) AuditDistroList-1.xlsx to make sure the email implementation of UHC Cirrus and HCSC is okay for EDM | F10: On Hold | G10: 2026-04-27
A11: IT-3016920 | B11: Copy files From Nile Prod Raw path to Nile QC Raw path - Aetna Trad | C11: Hi Team, Could you please copy the below mentioned files from the Nile PROD location to the Nile QC location? for the last week files, 04/19/2026 to latest. This request is critical as we have early communicated with prod support team. Nile PROD RAW PATH (Source): /dataingestionprod/raw/unrestricted/5-aetna-traditional Nile Dev RAW PATH (Target): /dataingestionqc/raw/unrestricted/5-aetna-traditional Once copied to QC folder, the owner should be set to "svcpnilediqcraw" and group should be set to "qcunrestricted" and permissions should be 75 | D11: Files Copied | E11: Files Copied | F11: Closed | G11: 2026-04-27
A12: IT-3016913 | B12: Copy files From Nile Prod Raw path to Nile QC Raw path - Aetna Trad | C12: Hi Team, Could you please copy the below mentioned files from the Nile PROD location to the Nile QC location? for the last week files, 04/19/2026 to latest. This request is critical as we have early communicated with prod support team. Nile PROD RAW PATH (Source): /dataingestionprod/raw/unrestricted/5-aetna-traditional Nile Dev RAW PATH (Target): /dataingestionqc/raw/unrestricted/5-aetna-traditional Once copied to QC folder, the owner should be set to "svcpnilediqcraw" and group should be set to "qcunrestricted" and permissions should be 75 | D12: Files are already copied | E12: Files are already copied | F12: Closed | G12: 2026-04-27
A13: IT-3016136 | B13: Update spooler name | C13: Hi Team, Could you please update the spooler name in prod? Before : Wellcare-Wellcare_Actian_PBM_MTH_notouch New name : Wellcare-Wellcare_notouch Thank you! | D13: Hi Varghese, Shilpa Anna updated the spooler name Thanks | E13: Updated Spooler name | F13: Closed | G13: 2026-04-27
A14: IT-3016120 | B14: Move two Aetna Trad files to different folders | C14: In HDFS (nile prod server), please move the following files to new locations. Ultimately we want the parent folder of these files to represent a different date (20260411 vs 20260427). Source files: /dataingestiondev/raw/unrestricted/5-aetna-traditional/20260427/M2603M1.ZIP /dataingestiondev/raw/unrestricted/5-aetna-traditional/20260427/M2603M2.ZIP Destinations: /dataingestiondev/raw/unrestricted/5-aetna-traditional/20260411/M2603M1.ZIP /dataingestiondev/raw/unrestricted/5-aetna-traditional/20260411/M2603M2.ZIP | D14: Hi Maguire, Patrick Files moved and updated permissions too please verify | E14: Files moved and updated permissions too | F14: Closed | G14: 2026-04-27
A15: IT-3016008 | B15: Requesting information for Cigna Gross ID amount dataset | C15: We are looking to learn information on Cigna Gross ID amount dataset as it relates to if it is provided to Nile and if so how and where it can accessed. | F15: In Progress (HD1) | G15: 2026-04-27
A16: IT-3015029 | B16: Removing unused spoolers with a retention period of ‘-1’ from the production environment. | C16: Removed published spoolers with a retention period of -1 from the production environment, as they were no longer in use. A backup was taken by importing and saving them in a folder prior to deletion. Below is the list of spoolers that were removed from production. | D16: Deleted date: 22-04-2026 | E16: Removed the unused spoolers. | F16: Closed | G16: 2026-04-27
